<?xml version="1.0"?>
<robot name="simple_two_wheel_robot" xmlns:xacro="http://www.ros.org/wiki/xacro">

  <!-- Base Link -->
  <link name="base_link">
    <visual>
      <geometry>
        <box size="0.4 0.3 0.1"/>
      </geometry>
      <origin xyz="0 0 0.05"/>
      <material name="blue"/>
    </visual>
    <collision>
      <geometry>
        <box size="0.4 0.3 0.1"/>
      </geometry>
      <origin xyz="0 0 0.05"/>
    </collision>
    <inertial>
      <mass value="1.0"/>
      <inertia ixx="0.1" ixy="0.0" ixz="0.0"
               iyy="0.1" iyz="0.0"
               izz="0.1"/>
    </inertial>
  </link>

  <!-- Wheels -->
  <xacro:macro name="wheel" params="prefix x y">
    <link name="${prefix}_wheel">
      <visual>
        <geometry>
          <cylinder radius="0.05" length="0.02"/>
        </geometry>
        <origin xyz="0 0 0" rpy="1.5708 0 0"/>
        <material name="black"/>
      </visual>
      <collision>
        <geometry>
          <cylinder radius="0.05" length="0.02"/>
        </geometry>
        <origin xyz="0 0 0" rpy="1.5708 0 0"/>
      </collision>
      <inertial>
        <mass value="0.2"/>
        <inertia ixx="0.01" ixy="0.0" ixz="0.0"
                 iyy="0.01" iyz="0.0"
                 izz="0.01"/>
      </inertial>
    </link>

    <joint name="${prefix}_wheel_joint" type="continuous">
      <parent link="base_link"/>
      <child link="${prefix}_wheel"/>
      <origin xyz="${x} ${y} 0.01"/>
      <axis xyz="0 1 0"/>
      <limit effort="1.0" velocity="10.0"/>
      <dynamics damping="0.1" friction="0.1"/>
    </joint>
  </xacro:macro>

  <!-- Left & Right Wheels -->
  <xacro:wheel prefix="left" x="0.15" y="0.15"/>
  <xacro:wheel prefix="right" x="0.15" y="-0.15"/>

  <!-- Gazebo plugins -->
  <gazebo>
    <plugin name="diff_drive_controller" filename="libgazebo_ros_diff_drive.so">
      <ros>
        <namespace>/</namespace>
      </ros>
      <left_joint>left_wheel_joint</left_joint>
      <right_joint>right_wheel_joint</right_joint>
      <wheel_separation>0.3</wheel_separation>
      <wheel_diameter>0.1</wheel_diameter>
      <robot_base_frame>base_link</robot_base_frame>
      <update_rate>50.0</update_rate>
      <publish_odom>true</publish_odom>
      <publish_odom_tf>true</publish_odom_tf>
      <odometry_frame>odom</odometry_frame>
      <cmd_vel_topic>cmd_vel</cmd_vel_topic>
      <odometry_topic>odom</odometry_topic>
    </plugin>
  </gazebo>

</robot>
